2025-10-13 22:05:16,988 - discord.app_commands.tree - ERROR - Ignoring exception in autocomplete for 'quote'
Traceback (most recent call last):
  File "/Users/aidaewor/Dev/volaris/venv/lib/python3.13/site-packages/discord/app_commands/tree.py", line 1302, in _call
    await command._invoke_autocomplete(interaction, focused, namespace)
  File "/Users/aidaewor/Dev/volaris/venv/lib/python3.13/site-packages/discord/app_commands/commands.py", line 927, in _invoke_autocomplete
    await interaction.response.autocomplete(choices)
  File "/Users/aidaewor/Dev/volaris/venv/lib/python3.13/site-packages/discord/interactions.py", line 1093, in autocomplete
    await adapter.create_interaction_response(
    ...<6 lines>...
    )
  File "/Users/aidaewor/Dev/volaris/venv/lib/python3.13/site-packages/discord/webhook/async_.py", line 223, in request
    raise HTTPException(response, data)
discord.errors.HTTPException: 400 Bad Request (error code: 40060): Interaction has already been acknowledged.
2025-10-13 22:05:17,354 - discord.app_commands.tree - ERROR - Ignoring exception in autocomplete for 'quote'
Traceback (most recent call last):
  File "/Users/aidaewor/Dev/volaris/venv/lib/python3.13/site-packages/discord/app_commands/tree.py", line 1302, in _call
    await command._invoke_autocomplete(interaction, focused, namespace)
  File "/Users/aidaewor/Dev/volaris/venv/lib/python3.13/site-packages/discord/app_commands/commands.py", line 927, in _invoke_autocomplete
    await interaction.response.autocomplete(choices)
  File "/Users/aidaewor/Dev/volaris/venv/lib/python3.13/site-packages/discord/interactions.py", line 1093, in autocomplete
    await adapter.create_interaction_response(
    ...<6 lines>...
    )
  File "/Users/aidaewor/Dev/volaris/venv/lib/python3.13/site-packages/discord/webhook/async_.py", line 223, in request
    raise HTTPException(response, data)
discord.errors.HTTPException: 400 Bad Request (error code: 40060): Interaction has already been acknowledged.
2025-10-13 22:05:18,199 - discord.app_commands.tree - ERROR - Ignoring exception in autocomplete for 'quote'
Traceback (most recent call last):
  File "/Users/aidaewor/Dev/volaris/venv/lib/python3.13/site-packages/discord/app_commands/tree.py", line 1302, in _call
    await command._invoke_autocomplete(interaction, focused, namespace)
  File "/Users/aidaewor/Dev/volaris/venv/lib/python3.13/site-packages/discord/app_commands/commands.py", line 927, in _invoke_autocomplete
    await interaction.response.autocomplete(choices)
  File "/Users/aidaewor/Dev/volaris/venv/lib/python3.13/site-packages/discord/interactions.py", line 1093, in autocomplete
    await adapter.create_interaction_response(
    ...<6 lines>...
    )
  File "/Users/aidaewor/Dev/volaris/venv/lib/python3.13/site-packages/discord/webhook/async_.py", line 223, in request
    raise HTTPException(response, data)
discord.errors.HTTPException: 400 Bad Request (error code: 40060): Interaction has already been acknowledged.
2025-10-13 22:05:18,832 - discord.app_commands.tree - ERROR - Ignoring exception in autocomplete for 'quote'
Traceback (most recent call last):
  File "/Users/aidaewor/Dev/volaris/venv/lib/python3.13/site-packages/discord/app_commands/tree.py", line 1302, in _call
    await command._invoke_autocomplete(interaction, focused, namespace)
  File "/Users/aidaewor/Dev/volaris/venv/lib/python3.13/site-packages/discord/app_commands/commands.py", line 927, in _invoke_autocomplete
    await interaction.response.autocomplete(choices)
  File "/Users/aidaewor/Dev/volaris/venv/lib/python3.13/site-packages/discord/interactions.py", line 1093, in autocomplete
    await adapter.create_interaction_response(
    ...<6 lines>...
    )
  File "/Users/aidaewor/Dev/volaris/venv/lib/python3.13/site-packages/discord/webhook/async_.py", line 221, in request
    raise NotFound(response, data)
discord.errors.NotFound: 404 Not Found (error code: 10062): Unknown interaction
2025-10-13 22:05:20,240 - discord.app_commands.tree - ERROR - Ignoring exception in command 'quote'
Traceback (most recent call last):
  File "/Users/aidaewor/Dev/volaris/venv/lib/python3.13/site-packages/discord/app_commands/commands.py", line 857, in _do_call
    return await self._callback(self.binding, interaction, **params)  # type: ignore
           ^^^^^^^^^^^^^^^^^^^^^^^^^^^^^^^^^^^^^^^^^^^^^^^^^^^^^^^^^
  File "/Users/aidaewor/Dev/volaris/app/alerts/cogs/market_data.py", line 278, in quote
    await interaction.response.defer()
  File "/Users/aidaewor/Dev/volaris/venv/lib/python3.13/site-packages/discord/interactions.py", line 709, in defer
    await adapter.create_interaction_response(
    ...<6 lines>...
    )
  File "/Users/aidaewor/Dev/volaris/venv/lib/python3.13/site-packages/discord/webhook/async_.py", line 223, in request
    raise HTTPException(response, data)
discord.errors.HTTPException: 400 Bad Request (error code: 40060): Interaction has already been acknowledged.

The above exception was the direct cause of the following exception:

Traceback (most recent call last):
  File "/Users/aidaewor/Dev/volaris/venv/lib/python3.13/site-packages/discord/app_commands/tree.py", line 1310, in _call
    await command._invoke_with_namespace(interaction, namespace)
  File "/Users/aidaewor/Dev/volaris/venv/lib/python3.13/site-packages/discord/app_commands/commands.py", line 883, in _invoke_with_namespace
    return await self._do_call(interaction, transformed_values)
           ^^^^^^^^^^^^^^^^^^^^^^^^^^^^^^^^^^^^^^^^^^^^^^^^^^^^
  File "/Users/aidaewor/Dev/volaris/venv/lib/python3.13/site-packages/discord/app_commands/commands.py", line 876, in _do_call
    raise CommandInvokeError(self, e) from e
discord.app_commands.errors.CommandInvokeError: Command 'quote' raised an exception: HTTPException: 400 Bad Request (error code: 40060): Interaction has already been acknowledged.